											Excepciones
											
											
		Las excepciones tambien son objetos , que tiene su nombre y su mensaje.
		Para entender la excepcion hay que comprender el mensaje de error
		
		
		
		
					//nombre de la exception 	//el mensaje de que sucedio, a veces lo tira
		java.lang.ArithmeticException: / by zero		
	at flujo.metodo2(flujo.java:21)			// 
	at flujo.metodo1(flujo.java:13)			//	la traza de la pila(stack trace)	 
	at flujo.main(flujo.java:8)				//
	
	
	
	
		Podemos avisarle a java donde creemos que puede haber una bomba, un error, con lads palabras claves 
		
		
		Try{
		}catch( ){
		}
		
		try es intenta(intenta hacerlo)
		
		catch es atrapa(atrapa el error)
		
		
		try no puede existir sin catch por si hay un error
		
		
		
		 try {
		    	int num=0;
			      int resultado=i/num;
			      System.out.println(resultado);
			      
			} catch (ArithmeticException exception ) {
				
				System.out.println(exception.getMessage());
				exception.printStackTrace();
				
			} 
			
			
			
			resultado:
			
			
			
			Inicio de main
Inicio do metodo1
Inicio de metodo2
1
/ by zero
2
java.lang.ArithmeticException: / by zero
	at flujo.metodo2(flujo.java:22)
	at flujo.metodo1(flujo.java:13)
	at flujo.main(flujo.java:8)
/ by zero
java.lang.ArithmeticException: / by zero
	at flujo.metodo2(flujo.java:22)
	at flujo.metodo1(flujo.java:13)
	at flujo.main(flujo.java:8)
3
/ by zero
java.lang.ArithmeticException: / by zero
	at flujo.metodo2(flujo.java:22)
	at flujo.metodo1(flujo.java:13)
	at flujo.main(flujo.java:8)
4
java.lang.ArithmeticException: / by zero
/ by zero
	at flujo.metodo2(flujo.java:22)
	at flujo.metodo1(flujo.java:13)
5
/ by zero
	at flujo.main(flujo.java:8)
java.lang.ArithmeticException: / by zero
	at flujo.metodo2(flujo.java:22)
	at flujo.metodo1(flujo.java:13)
	at flujo.main(flujo.java:8)
Fin de metodo2
Fin de metodo1
Fin de main
			
			
			
			
			muestrar otros resultado por que supo contener el error, mostrarlo y continuar ejecutando el codigo
			
			
			
			
			Se puede poner varios catch o usar el operador O "|"
			
			
			 try {
		    	int num=0;
			      int resultado=i/num;
			      System.out.println(resultado);
			      
			} catch (ArithmeticException | NullPointerException exception ) {
				System.out.println("Atrapo excepcion");
				System.out.println(exception.getMessage());
				exception.printStackTrace();
				
			}  
			
			
									VER QUE ATRAPA DISTINTOS EXCEPCIONES
									
									
	
	
public class flujo {

	public static void main(String[] args) {
		System.out.println("Inicio de main");
		metodo1();
		System.out.println("Fin de main");
	}

	public static void metodo1() {
		System.out.println("Inicio do metodo1");
		metodo2();
		System.out.println("Fin de metodo1");
	}

	public static void metodo2() {
		System.out.println("Inicio de metodo2");
		for (int i = 1; i <= 5; i++) {
			System.out.println(i);
			try {

				if (i == 3) {

					int num = 0;
					int resultado = i / num;
					System.out.println(resultado);
				}
				
				String test=null;
				System.out.println(test.toString());
				
				
			} catch (ArithmeticException | NullPointerException exception) {
				System.out.println("Atrapo excepcion");
				System.out.println(exception.getMessage());
				exception.printStackTrace();

			}
		}
		System.out.println("Fin de metodo2");
	}

}





												RESULTADO
												
												
Inicio de main
Inicio do metodo1
Inicio de metodo2
1
Atrapo excepcion
Cannot invoke "String.toString()" because "test" is null
java.lang.NullPointerException: Cannot invoke "String.toString()" because "test" is null
	at flujo.metodo2(flujo.java:30)
	at flujo.metodo1(flujo.java:12)
	at flujo.main(flujo.java:6)
2
Atrapo excepcion
Cannot invoke "String.toString()" because "test" is null
java.lang.NullPointerException: Cannot invoke "String.toString()" because "test" is null
	at flujo.metodo2(flujo.java:30)
	at flujo.metodo1(flujo.java:12)
	at flujo.main(flujo.java:6)
3
Atrapo excepcion
/ by zero
java.lang.ArithmeticException: / by zero
	at flujo.metodo2(flujo.java:25)
	at flujo.metodo1(flujo.java:12)
	at flujo.main(flujo.java:6)
4
Atrapo excepcion
Cannot invoke "String.toString()" because "test" is null
java.lang.NullPointerException: Cannot invoke "String.toString()" because "test" is null
	at flujo.metodo2(flujo.java:30)
	at flujo.metodo1(flujo.java:12)
	at flujo.main(flujo.java:6)
5
Atrapo excepcion
Cannot invoke "String.toString()" because "test" is null
java.lang.NullPointerException: Cannot invoke "String.toString()" because "test" is null
	at flujo.metodo2(flujo.java:30)
	at flujo.metodo1(flujo.java:12)
	at flujo.main(flujo.java:6)
Fin de metodo2
Fin de metodo1
Fin de main
													
													
													
													
													
													
													
													
													
													
													
													
													
													
													
													
													
													
													
													
													
															CREANDO EXCEPCIONES
															
															
															
															
															
Al crear excepciones solo podemos extender de la clase Exception ya que si lo hace de Thtowable rompemos la norma de JAVA de que exista 2 tipos de
errores, el que configuramos nosotros y lo que tira el JVM		
	Para poder extender de la clase Exception directamente tenemos que declarar un try catch si o si y en el metodo declarar el throws Miexception{}
Ya que si extendermos de exception es por estamos seguro que nuestro metodo tirara nuestra exception encambio con RintimeException puede ser que tire
esa exception 						
															
															
															
															
															
	Cuenta cuenta=new Cuenta();
	throw new ArithmeticException();
	
	//despues del throw no podes escribir nada mas
	
	
															el throw significa lanzar
									
									
									Resultado
									
Inicio de main
Inicio do metodo1
Inicio de metodo2
Exception in thread "main" java.lang.ArithmeticException
	at flujo.metodo2(flujo.java:18)
	at flujo.metodo1(flujo.java:12)
	at flujo.main(flujo.java:6)
															
				
				
				
											CREAMOS Y EXPLOTAMOS NUESTRA BOMBA
											
											

public class flujo {

	public static void main(String[] args) {
		System.out.println("Inicio de main");
		metodo1();
		System.out.println("Fin de main");
	}

	public static void metodo1() {
		System.out.println("Inicio do metodo1");
		metodo2();
		System.out.println("Fin de metodo1");
	}

	public static void metodo2() {
		System.out.println("Inicio de metodo2");
		throw new Miexcepcion("Mi exception fue lanzadaaaaaaa");
		
		
	}

}





										RESULTADO
										
					Inicio de main
Inicio do metodo1
Inicio de metodo2
Exception in thread "main" Miexcepcion: Mi exception fue lanzadaaaaaaa
	at flujo.metodo2(flujo.java:18)
	at flujo.metodo1(flujo.java:12)
	at flujo.main(flujo.java:6)
										
										
										
										CREAMOS EXCEPCION Y LA EJECUTAMOS
										



public class flujo {

	public static void main(String[] args) {
		System.out.println("Inicio de main");
		metodo1();
		System.out.println("Fin de main");
	}

	public static void metodo1() {
		System.out.println("Inicio do metodo1");
		try {
			metodo2();
			
		} catch (Miexcepcion e) {
			e.printStackTrace();
		}
		System.out.println("Fin de metodo1");
	}

	public static void metodo2() {
		System.out.println("Inicio de metodo2");
		throw new Miexcepcion("Mi exception fue lanzadaaaaaaa");
		
		
	}

}




										RESULTADOS
										
										
	Inicio de main
Inicio do metodo1
Inicio de metodo2
Miexcepcion: Mi exception fue lanzadaaaaaaa
	at flujo.metodo2(flujo.java:23)
	at flujo.metodo1(flujo.java:13)
	at flujo.main(flujo.java:6)
Fin de metodo1
Fin de main
										
			
			
			
			
			
			
			
			
										EJEMPLO DE HERENCIA DE EXCEPTION



	
public class Miexcepcion extends Exception {

	
	public Miexcepcion() {
		super();
	}
	
	
	public Miexcepcion(String mensaje) {
		super(mensaje);
	}
	
	
}
	
	
	
	
	
	
	
public class flujo {

	public static void main(String[] args) {
		System.out.println("Inicio de main");
		metodo1();
		System.out.println("Fin de main");
	}

	public static void metodo1() {
		System.out.println("Inicio do metodo1");
		try {
			metodo2();
			
		} catch (Miexcepcion e) {
			e.printStackTrace();
		}
		System.out.println("Fin de metodo1");
	}

	public static void metodo2()  throws Miexcepcion{
		System.out.println("Inicio de metodo2");
		throw new Miexcepcion("Mi exception fue lanzadaaaaaaa");
		
		
	}

}										
										









										
										UNCHECKED Y CHCKED
										
Uncheked no son verificadas por el compilador puede que lanze o puede que no lanze el compilador, en el caso del cheked si
nos va  a obligar a tratar esa excepcion en el codigo cuando es lanzada sino no va a compilar										
										
										
										
										
										
										
										
										
										
										
										
										
										
		Existe una gran jerarquía de clases que representan excepciones. Por ejemplo, ArithmeticException es hija de RuntimeException, que hereda de Exception, que a su vez es hija de la clase de excepciones más ancestral, Throwable. Conocer bien esta jerarquía significa saber cómo usar las excepciones en su aplicación.
		
		
		Throwable es la clase que debe extenderse para poder lanzar un objeto en la pila (usando la palabra reservada throw)
		
		Es en la clase Throwable donde tenemos casi todo el código relacionado con las excepciones, incluyendo getMessage() e printStackTrace (). El resto de la jerarquía tiene solo algunas sobrecargas de constructores para comunicar mensajes específicos.
		
		La jerarquía que comenzó con la clase Throwable se divide en excepciones y errores. Las excepciones se utilizan en los códigos de aplicación. Los errores son utilizados exclusivamente por la máquina virtual.
		
		Las clases que heredan de Error se utilizan para informar errores en la máquina virtual. Los desarrolladores de aplicaciones no deben crear errores que hereden de Error.
		
		StackOverflowError es un error de máquina virtual para informar que la pila de ejecución no tiene más memoria.
		
		Las excepciones se dividen en dos categorías amplias: las que el compilador comprueba obligatoriamente y las que no.
		
		Los primeros se denominan checked y se crean por pertenecer a una jerarquía que no pasa RuntimeException.
		
		Los segundos están unchecked y se crean como descendientes de RuntimeException.				

		
		
		
		
		
		
		
		
		
		
		////////////////////
		
		
		
		
		
public class flujo {

	public static void main(String[] args) {
		System.out.println("Inicio de main");
		metodo1();
		System.out.println("Fin de main");
	}

	public static void metodo1() {
		System.out.println("Inicio do metodo1");
		try {
			metodo2();
			
		} catch (Miexcepcion e) {		//Exception
			e.printStackTrace();
		}
		System.out.println("Fin de metodo1");
	}

	public static void metodo2()  throws Miexcepcion{
		System.out.println("Inicio de metodo2");
		throw new Miexcepcion("Mi exception fue lanzadaaaaaaa");
		
		
	}

}
		
		
		Podemos directamente poner Exception pero es meejor ser mas especifico para el proximo programador 














---------------------------------------------------------Excepcion en el proyecto del banco de por que no pude sacar dinero-------------------------


Creamos una exception en cual aplicamos en la clase Cuenta y sus metodos pero luego modificamos la exception, la volvimos Chedcked entonces extendia de
Exception y tuvimos que agregar los try catch o en los metodos los throws de la exception creada

		
		
		
		
		
		
		
		
		
		
---------------------------------------------------------APLICACIONES DISTRIBUIDAS-------------------------
		
		Es un conjunto de aplicaciones que interactuan entre si para satisfacer las reglas del negocio
		
		
		
		
		
				
---------------------------------------------------------Finally del try catch-------------------------
		
		
		Como una conexion a base de datos necesitamos siempre cerrar la conexion, utilizando try catch 
		no podriamos tener seguramente una buena seguridad ya que tenemos que repetir codigo y dependiendo 
		de que no se borre la aplicacion de la exception. 
		
		
		
		public class TextConexion {

	public static void main(String[] args) {
		Conexion conexion=new Conexion();
		try {
			conexion.leerDatos();
			conexion.cerrar();
			
		} catch (IllegalStateException e) {
			// TODO: handle exception
			e.getStackTrace();
			conexion.cerrar();
		}
	}
	
	
}


se repite el metodo cerrar



							
							
							
							PARA SOLUCIONAR ESO ESTA EL FINALLY
							
							
							
Pase lo que pase siempre se va a ejecutar lo que este en finally. Finally es opcional 



		
		